Traceback (most recent call last):
  File "/usr/local/lib/python3.8/dist-packages/jupyter_cache/executors/utils.py", line 58, in single_nb_execution
    executenb(
  File "/usr/local/lib/python3.8/dist-packages/nbclient/client.py", line 1204, in execute
    return NotebookClient(nb=nb, resources=resources, km=km, **kwargs).execute()
  File "/usr/local/lib/python3.8/dist-packages/nbclient/util.py", line 84, in wrapped
    return just_run(coro(*args, **kwargs))
  File "/usr/local/lib/python3.8/dist-packages/nbclient/util.py", line 62, in just_run
    return loop.run_until_complete(coro)
  File "/usr/lib/python3.8/asyncio/base_events.py", line 616, in run_until_complete
    return future.result()
  File "/usr/local/lib/python3.8/dist-packages/nbclient/client.py", line 663, in async_execute
    await self.async_execute_cell(
  File "/usr/local/lib/python3.8/dist-packages/nbclient/client.py", line 965, in async_execute_cell
    await self._check_raise_for_error(cell, cell_index, exec_reply)
  File "/usr/local/lib/python3.8/dist-packages/nbclient/client.py", line 862, in _check_raise_for_error
    raise CellExecutionError.from_cell_and_msg(cell, exec_reply_content)
nbclient.exceptions.CellExecutionError: An error occurred while executing the following cell:
------------------
connection = psycopg2.connect(
    host="trumpet.db.elephantsql.com",
    database="prosain{210411100112}",
    user="xtzkuaqv",
    password="kOupjNX9j0ny4IIeAWJpC014w6HPFTA38",
    port="5432"
)
------------------

[0;31m[0m
[0;31mOperationalError[0mTraceback (most recent call last)
[0;32m<ipython-input-3-6539a8953336>[0m in [0;36m<module>[0;34m[0m
[0;32m----> 1[0;31m connection = psycopg2.connect(
[0m[1;32m      2[0m     [0mhost[0m[0;34m=[0m[0;34m"trumpet.db.elephantsql.com"[0m[0;34m,[0m[0;34m[0m[0;34m[0m[0m
[1;32m      3[0m     [0mdatabase[0m[0;34m=[0m[0;34m"prosain{210411100112}"[0m[0;34m,[0m[0;34m[0m[0;34m[0m[0m
[1;32m      4[0m     [0muser[0m[0;34m=[0m[0;34m"xtzkuaqv"[0m[0;34m,[0m[0;34m[0m[0;34m[0m[0m
[1;32m      5[0m     [0mpassword[0m[0;34m=[0m[0;34m"kOupjNX9j0ny4IIeAWJpC014w6HPFTA38"[0m[0;34m,[0m[0;34m[0m[0;34m[0m[0m

[0;32m/usr/local/lib/python3.8/dist-packages/psycopg2/__init__.py[0m in [0;36mconnect[0;34m(dsn, connection_factory, cursor_factory, **kwargs)[0m
[1;32m    120[0m [0;34m[0m[0m
[1;32m    121[0m     [0mdsn[0m [0;34m=[0m [0m_ext[0m[0;34m.[0m[0mmake_dsn[0m[0;34m([0m[0mdsn[0m[0;34m,[0m [0;34m**[0m[0mkwargs[0m[0;34m)[0m[0;34m[0m[0;34m[0m[0m
[0;32m--> 122[0;31m     [0mconn[0m [0;34m=[0m [0m_connect[0m[0;34m([0m[0mdsn[0m[0;34m,[0m [0mconnection_factory[0m[0;34m=[0m[0mconnection_factory[0m[0;34m,[0m [0;34m**[0m[0mkwasync[0m[0;34m)[0m[0;34m[0m[0;34m[0m[0m
[0m[1;32m    123[0m     [0;32mif[0m [0mcursor_factory[0m [0;32mis[0m [0;32mnot[0m [0;32mNone[0m[0;34m:[0m[0;34m[0m[0;34m[0m[0m
[1;32m    124[0m         [0mconn[0m[0;34m.[0m[0mcursor_factory[0m [0;34m=[0m [0mcursor_factory[0m[0;34m[0m[0;34m[0m[0m

[0;31mOperationalError[0m: FATAL:  no pg_hba.conf entry for host "34.147.24.135", user "xtzkuaqv", database "prosain{210411100112}", SSL on
FATAL:  no pg_hba.conf entry for host "34.147.24.135", user "xtzkuaqv", database "prosain{210411100112}", SSL off

OperationalError: FATAL:  no pg_hba.conf entry for host "34.147.24.135", user "xtzkuaqv", database "prosain{210411100112}", SSL on
FATAL:  no pg_hba.conf entry for host "34.147.24.135", user "xtzkuaqv", database "prosain{210411100112}", SSL off


