Traceback (most recent call last):
  File "/usr/local/lib/python3.10/dist-packages/jupyter_cache/executors/utils.py", line 58, in single_nb_execution
    executenb(
  File "/usr/local/lib/python3.10/dist-packages/nbclient/client.py", line 1305, in execute
    return NotebookClient(nb=nb, resources=resources, km=km, **kwargs).execute()
  File "/usr/local/lib/python3.10/dist-packages/jupyter_core/utils/__init__.py", line 166, in wrapped
    return loop.run_until_complete(inner)
  File "/usr/lib/python3.10/asyncio/base_events.py", line 649, in run_until_complete
    return future.result()
  File "/usr/local/lib/python3.10/dist-packages/nbclient/client.py", line 705, in async_execute
    await self.async_execute_cell(
  File "/usr/local/lib/python3.10/dist-packages/nbclient/client.py", line 1058, in async_execute_cell
    await self._check_raise_for_error(cell, cell_index, exec_reply)
  File "/usr/local/lib/python3.10/dist-packages/nbclient/client.py", line 914, in _check_raise_for_error
    raise CellExecutionError.from_cell_and_msg(cell, exec_reply_content)
nbclient.exceptions.CellExecutionError: An error occurred while executing the following cell:
------------------
# later reload the pickle file
pca_reload = pk.load(open("pca.pkl",'rb'))
result_new = pca_reload .transform(X)
------------------


[0;31m[0m
[0;31mAttributeError[0mTraceback (most recent call last)
[0;32m<ipython-input-12-a64016296571>[0m in [0;36m<cell line: 3>[0;34m()[0m
[1;32m      1[0m [0;31m# later reload the pickle file[0m[0;34m[0m[0;34m[0m[0m
[1;32m      2[0m [0mpca_reload[0m [0;34m=[0m [0mpk[0m[0;34m.[0m[0mload[0m[0;34m([0m[0mopen[0m[0;34m([0m[0;34m"pca.pkl"[0m[0;34m,[0m[0;34m'rb'[0m[0;34m)[0m[0;34m)[0m[0;34m[0m[0;34m[0m[0m
[0;32m----> 3[0;31m [0mresult_new[0m [0;34m=[0m [0mpca_reload[0m [0;34m.[0m[0mtransform[0m[0;34m([0m[0mX[0m[0;34m)[0m[0;34m[0m[0;34m[0m[0m
[0m
[0;31mAttributeError[0m: 'function' object has no attribute 'transform'

